Workbook

Sheet IR Calculator
B2: Radiometric IR Emission Calculator | Planck / Stefan-Boltzmann
B4: Physical Constants (do not modify)
B5: h — Planck constant | C5: 6.6260701e-34 | D5: J·s
B6: c — Speed of light | C6: 299792458 | D6: m/s
B7: k — Boltzmann constant | C7: 1.380649e-23 | D7: J/K
B8: σ — Stefan-Boltzmann const | C8: 5.6703744e-08 | D8: W/m²K⁴
B10: Inputs (blue = editable)
B11: Temperature | C11: 150 | D11: °C | E11: Object surface temperature in Celsius
B12: Surface Area | C12: 0.05 | D12: m² | E12: Total radiating surface area (m²). E.g. 1-gal sphere ≈ 0.117 m²
B13: Emissivity ε | C13: 0.96 | D13: — | E13: 0 = perfect reflector · 1 = blackbody (water ≈ 0.96, Al polished ≈ 0.05)
B14: λ₁ Band start | C14: 8 | D14: µm | E14: Short-wavelength edge of spectral band of interest
B15: λ₂ Band end | C15: 10 | D15: µm | E15: Long-wavelength edge of spectral band of interest
B16: Integration steps N | C16: 500 | D16: — | E16: Steps for numerical Planck integral (100–500; 500 is plenty accurate)
B18: Derived Quantities
B19: Temperature T | C19: =C11+273.15 -> 423.15 | D19: K | E19: Converted from °C
B20: Peak wavelength λ_peak | C20: =2897.8/C19 -> 6.8481626 | D20: µm | E20: Wien displacement: λ_peak = 2897.8 / T(K)
B21: Total radiated power P_total | C21: =C13*C8*C19^4*C12 -> 87.263043 | D21: W | E21: ε · σ · T⁴ · A (all wavelengths, Stefan-Boltzmann)
B23: Band-Integrated Results (Planck numerical integration — see 'Integration' sheet)
B24: P_band (W in band) | C24: =Integration!C4 -> 1.4203157e-05 | D24: W | E24: Power emitted in [λ₁, λ₂] spectral band
B25: Band fraction | C25: =Integration!C5 -> 1.6276257e-07 | D25: % | E25: P_band / P_total
B26: Band irradiance | C26: =Integration!C6 -> 0.00028406315 | D26: W/m² | E26: P_band / A (band power per unit area)
B27: Spectral radiance λ_peak | C27: =Integration!C7 -> 55.56447 | D27: W/m²sr·µm | E27: Planck spectral radiance at peak wavelength
B30: Notes & Assumptions • Calculations assume thermal equilibrium and grey-body emission (uniform ε across band). • Surface area is the key size parameter — not mass or volume directly. • Planck integral uses midpoint rule: B(λ_mid,T)·Δλ summed over N steps per the Integration sheet. • Emissivity reference values: water ≈ 0.96 · human skin ≈ 0.97 · painted surfaces ≈ 0.90–0.95 · polished Al ≈ 0.05. • The 8–10 µm band is within the atmospheric transmission window used by thermal infrared cameras.

Sheet Integration
B1: Planck Band Integration — Midpoint Rule
B4: P_band (W) | C4: ='IR Calculator'!C13*'IR Calculator'!C12*PI()*SUMPRODUCT(IntStep_dL,IntStep_B)*0.000001 -> 1.4203157e-05
B5: Band fraction | C5: =C4/'IR Calculator'!C21 -> 1.6276257e-07
B6: Band irradiance W/m² | C6: =C4/'IR Calculator'!C12 -> 0.00028406315
B7: Radiance at λ_peak W/m²sr·µm | C7: =(2*'IR Calculator'!C5*('IR Calculator'!C6)^2/(('IR Calculator'!C20*0.000001)^5))/(EXP(MIN('IR Calculator'!C5*'IR Calculator'!C6/('IR Calculator'!C20*0.000001*'IR Calculator'!C7*'IR Calculator'!C19),700))-1)*0.000001 -> 55.56447
B10: Step i | C10: λ_mid (µm) | D10: Δλ (µm) | E10: B(λ,T) W/m²/sr/µm
B11: 1 | C11: ='IR Calculator'!C14+(1-0.5)*('IR Calculator'!C15-'IR Calculator'!C14)/MIN('IR Calculator'!C16,500) -> 8.002 | D11: =('IR Calculator'!C15-'IR Calculator'!C14)/MIN('IR Calculator'!C16,500) -> 0.004 | E11: =(2*'IR Calculator'!$C$5*'IR Calculator'!$C$6^2/((('IR Calculator'!C14+(1-0.5)*('IR Calculator'!C15-'IR Calculator'!C14)/MIN('IR Calculator'!C16,500))*0.000001)^5))/(EXP(MIN('IR Calculator'!$C$5*'IR Calculator'!$C$6/((('IR Calculator'!C14+(1-0.5)*('IR Calculator'!C15-'IR Calculator'!C14)/MIN('IR Calculator'!C16,500))*0.000001)*'IR Calculator'!$C$7*'IR Calculator'!$C$19),700))-1)*0.000001 -> 52.577946
B12: 2 | C12: ='IR Calculator'!C14+(2-0.5)*('IR Calculator'!C15-'IR Calculator'!C14)/MIN('IR Calculator'!C16,500) -> 8.006 | D12: =('IR Calculator'!C15-'IR Calculator'!C14)/MIN('IR Calculator'!C16,500) -> 0.004 | E12: =(2*'IR Calculator'!$C$5*'IR Calculator'!$C$6^2/((('IR Calculator'!C14+(2-0.5)*('IR Calculator'!C15-'IR Calculator'!C14)/MIN('IR Calculator'!C16,500))*0.000001)^5))/(EXP(MIN('IR Calculator'!$C$5*'IR Calculator'!$C$6/((('IR Calculator'!C14+(2-0.5)*('IR Calculator'!C15-'IR Calculator'!C14)/MIN('IR Calculator'!C16,500))*0.000001)*'IR Calculator'!$C$7*'IR Calculator'!$C$19),700))-1)*0.000001 -> 52.55981
B13: 3 | C13: ='IR Calculator'!C14+(3-0.5)*('IR Calculator'!C15-'IR Calculator'!C14)/MIN('IR Calculator'!C16,500) -> 8.01 | D13: =('IR Calculator'!C15-'IR Calculator'!C14)/MIN('IR Calculator'!C16,500) -> 0.004 | E13: =(2*'IR Calculator'!$C$5*'IR Calculator'!$C$6^2/((('IR Calculator'!C14+(3-0.5)*('IR Calculator'!C15-'IR Calculator'!C14)/MIN('IR Calculator'!C16,500))*0.000001)^5))/(EXP(MIN('IR Calculator'!$C$5*'IR Calculator'!$C$6/((('IR Calculator'!C14+(3-0.5)*('IR Calculator'!C15-'IR Calculator'!C14)/MIN('IR Calculator'!C16,500))*0.000001)*'IR Calculator'!$C$7*'IR Calculator'!$C$19),700))-1)*0.000001 -> 52.541636
B14: 4 | C14: ='IR Calculator'!C14+(4-0.5)*('IR Calculator'!C15-'IR Calculator'!C14)/MIN('IR Calculator'!C16,500) -> 8.014 | D14: =('IR Calculator'!C15-'IR Calculator'!C14)/MIN('IR Calculator'!C16,500) -> 0.004 | E14: =(2*'IR Calculator'!$C$5*'IR Calculator'!$C$6^2/((('IR Calculator'!C14+(4-0.5)*('IR Calculator'!C15-'IR Calculator'!C14)/MIN('IR Calculator'!C16,500))*0.000001)^5))/(EXP(MIN('IR Calculator'!$C$5*'IR Calculator'!$C$6/((('IR Calculator'!C14+(4-0.5)*('IR Calculator'!C15-'IR Calculator'!C14)/MIN('IR Calculator'!C16,500))*0.000001)*'IR Calculator'!$C$7*'IR Calculator'!$C$19),700))-1)*0.000001 -> 52.523425
B15: 5 | C15: ='IR Calculator'!C14+(5-0.5)*('IR Calculator'!C15-'IR Calculator'!C14)/MIN('IR Calculator'!C16,500) -> 8.018 | D15: =('IR Calculator'!C15-'IR Calculator'!C14)/MIN('IR Calculator'!C16,500) -> 0.004 | E15: =(2*'IR Calculator'!$C$5*'IR Calculator'!$C$6^2/((('IR Calculator'!C14+(5-0.5)*('IR Calculator'!C15-'IR Calculator'!C14)/MIN('IR Calculator'!C16,500))*0.000001)^5))/(EXP(MIN('IR Calculator'!$C$5*'IR Calculator'!$C$6/((('IR Calculator'!C14+(5-0.5)*('IR Calculator'!C15-'IR Calculator'!C14)/MIN('IR Calculator'!C16,500))*0.000001)*'IR Calculator'!$C$7*'IR Calculator'!$C$19),700))-1)*0.000001 -> 52.505176
B16: 6 | C16: ='IR Calculator'!C14+(6-0.5)*('IR Calculator'!C15-'IR Calculator'!C14)/MIN('IR Calculator'!C16,500) -> 8.022 | D16: =('IR Calculator'!C15-'IR Calculator'!C14)/MIN('IR Calculator'!C16,500) -> 0.004 | E16: =(2*'IR Calculator'!$C$5*'IR Calculator'!$C$6^2/((('IR Calculator'!C14+(6-0.5)*('IR Calculator'!C15-'IR Calculator'!C14)/MIN('IR Calculator'!C16,500))*0.000001)^5))/(EXP(MIN('IR Calculator'!$C$5*'IR Calculator'!$C$6/((('IR Calculator'!C14+(6-0.5)*('IR Calculator'!C15-'IR Calculator'!C14)/MIN('IR Calculator'!C16,500))*0.000001)*'IR Calculator'!$C$7*'IR Calculator'!$C$19),700))-1)*0.000001 -> 52.48689
B17: 7 | C17: ='IR Calculator'!C14+(7-0.5)*('IR Calculator'!C15-'IR Calculator'!C14)/MIN('IR Calculator'!C16,500) -> 8.026 | D17: =('IR Calculator'!C15-'IR Calculator'!C14)/MIN('IR Calculator'!C16,500) -> 0.004 | E17: =(2*'IR Calculator'!$C$5*'IR Calculator'!$C$6^2/((('IR Calculator'!C14+(7-0.5)*('IR Calculator'!C15-'IR Calculator'!C14)/MIN('IR Calculator'!C16,500))*0.000001)^5))/(EXP(MIN('IR Calculator'!$C$5*'IR Calculator'!$C$6/((('IR Calculator'!C14+(7-0.5)*('IR Calculator'!C15-'IR Calculator'!C14)/MIN('IR Calculator'!C16,500))*0.000001)*'IR Calculator'!$C$7*'IR Calculator'!$C$19),700))-1)*0.000001 -> 52.468567
B18: 8 | C18: ='IR Calculator'!C14+(8-0.5)*('IR Calculator'!C15-'IR Calculator'!C14)/MIN('IR Calculator'!C16,500) -> 8.03 | D18: =('IR Calculator'!C15-'IR Calculator'!C14)/MIN('IR Calculator'!C16,500) -> 0.004 | E18: =(2*'IR Calculator'!$C$5*'IR Calculator'!$C$6^2/((('IR Calculator'!C14+(8-0.5)*('IR Calculator'!C15-'IR Calculator'!C14)/MIN('IR Calculator'!C16,500))*0.000001)^5))/(EXP(MIN('IR Calculator'!$C$5*'IR Calculator'!$C$6/((('IR Calculator'!C14+(8-0.5)*('IR Calculator'!C15-'IR Calculator'!C14)/MIN('IR Calculator'!C16,500))*0.000001)*'IR Calculator'!$C$7*'IR Calculator'!$C$19),700))-1)*0.000001 -> 52.450207
B19: 9 | C19: ='IR Calculator'!C14+(9-0.5)*('IR Calculator'!C15-'IR Calculator'!C14)/MIN('IR Calculator'!C16,500) -> 8.034 | D19: =('IR Calculator'!C15-'IR Calculator'!C14)/MIN('IR Calculator'!C16,500) -> 0.004 | E19: =(2*'IR Calculator'!$C$5*'IR Calculator'!$C$6^2/((('IR Calculator'!C14+(9-0.5)*('IR Calculator'!C15-'IR Calculator'!C14)/MIN('IR Calculator'!C16,500))*0.000001)^5))/(EXP(MIN('IR Calculator'!$C$5*'IR Calculator'!$C$6/((('IR Calculator'!C14+(9-0.5)*('IR Calculator'!C15-'IR Calculator'!C14)/MIN('IR Calculator'!C16,500))*0.000001)*'IR Calculator'!$C$7*'IR Calculator'!$C$19),700))-1)*0.000001 -> 52.431811
B20: 10 | C20: ='IR Calculator'!C14+(10-0.5)*('IR Calculator'!C15-'IR Calculator'!C14)/MIN('IR Calculator'!C16,500) -> 8.038 | D20: =('IR Calculator'!C15-'IR Calculator'!C14)/MIN('IR Calculator'!C16,500) -> 0.004 | E20: =(2*'IR Calculator'!$C$5*'IR Calculator'!$C$6^2/((('IR Calculator'!C14+(10-0.5)*('IR Calculator'!C15-'IR Calculator'!C14)/MIN('IR Calculator'!C16,500))*0.000001)^5))/(EXP(MIN('IR Calculator'!$C$5*'IR Calculator'!$C$6/((('IR Calculator'!C14+(10-0.5)*('IR Calculator'!C15-'IR Calculator'!C14)/MIN('IR Calculator'!C16,500))*0.000001)*'IR Calculator'!$C$7*'IR Calculator'!$C$19),700))-1)*0.000001 -> 52.413377
B21: 11 | C21: ='IR Calculator'!C14+(11-0.5)*('IR Calculator'!C15-'IR Calculator'!C14)/MIN('IR Calculator'!C16,500) -> 8.042 | D21: =('IR Calculator'!C15-'IR Calculator'!C14)/MIN('IR Calculator'!C16,500) -> 0.004 | E21: =(2*'IR Calculator'!$C$5*'IR Calculator'!$C$6^2/((('IR Calculator'!C14+(11-0.5)*('IR Calculator'!C15-'IR Calculator'!C14)/MIN('IR Calculator'!C16,500))*0.000001)^5))/(EXP(MIN('IR Calculator'!$C$5*'IR Calculator'!$C$6/((('IR Calculator'!C14+(11-0.5)*('IR Calculator'!C15-'IR Calculator'!C14)/MIN('IR Calculator'!C16,500))*0.000001)*'IR Calculator'!$C$7*'IR Calculator'!$C$19),700))-1)*0.000001 -> 52.394907
B22: 12 | C22: ='IR Calculator'!C14+(12-0.5)*('IR Calculator'!C15-'IR Calculator'!C14)/MIN('IR Calculator'!C16,500) -> 8.046 | D22: =('IR Calculator'!C15-'IR Calculator'!C14)/MIN('IR Calculator'!C16,500) -> 0.004 | E22: =(2*'IR Calculator'!$C$5*'IR Calculator'!$C$6^2/((('IR Calculator'!C14+(12-0.5)*('IR Calculator'!C15-'IR Calculator'!C14)/MIN('IR Calculator'!C16,500))*0.000001)^5))/(EXP(MIN('IR Calculator'!$C$5*'IR Calculator'!$C$6/((('IR Calculator'!C14+(12-0.5)*('IR Calculator'!C15-'IR Calculator'!C14)/MIN('IR Calculator'!C16,500))*0.000001)*'IR Calculator'!$C$7*'IR Calculator'!$C$19),700))-1)*0.000001 -> 52.3764
B23: 13 | C23: ='IR Calculator'!C14+(13-0.5)*('IR Calculator'!C15-'IR Calculator'!C14)/MIN('IR Calculator'!C16,500) -> 8.05 | D23: =('IR Calculator'!C15-'IR Calculator'!C14)/MIN('IR Calculator'!C16,500) -> 0.004 | E23: =(2*'IR Calculator'!$C$5*'IR Calculator'!$C$6^2/((('IR Calculator'!C14+(13-0.5)*('IR Calculator'!C15-'IR Calculator'!C14)/MIN('IR Calculator'!C16,500))*0.000001)^5))/(EXP(MIN('IR Calculator'!$C$5*'IR Calculator'!$C$6/((('IR Calculator'!C14+(13-0.5)*('IR Calculator'!C15-'IR Calculator'!C14)/MIN('IR Calculator'!C16,500))*0.000001)*'IR Calculator'!$C$7*'IR Calculator'!$C$19),700))-1)*0.000001 -> 52.357857
B24: 14 | C24: ='IR Calculator'!C14+(14-0.5)*('IR Calculator'!C15-'IR Calculator'!C14)/MIN('IR Calculator'!C16,500) -> 8.054 | D24: =('IR Calculator'!C15-'IR Calculator'!C14)/MIN('IR Calculator'!C16,500) -> 0.004 | E24: =(2*'IR Calculator'!$C$5*'IR Calculator'!$C$6^2/((('IR Calculator'!C14+(14-0.5)*('IR Calculator'!C15-'IR Calculator'!C14)/MIN('IR Calculator'!C16,500))*0.000001)^5))/(EXP(MIN('IR Calculator'!$C$5*'IR Calculator'!$C$6/((('IR Calculator'!C14+(14-0.5)*('IR Calculator'!C15-'IR Calculator'!C14)/MIN('IR Calculator'!C16,500))*0.000001)*'IR Calculator'!$C$7*'IR Calculator'!$C$19),700))-1)*0.000001 -> 52.339278
B25: 15 | C25: ='IR Calculator'!C14+(15-0.5)*('IR Calculator'!C15-'IR Calculator'!C14)/MIN('IR Calculator'!C16,500) -> 8.058 | D25: =('IR Calculator'!C15-'IR Calculator'!C14)/MIN('IR Calculator'!C16,500) -> 0.004 | E25: =(2*'IR Calculator'!$C$5*'IR Calculator'!$C$6^2/((('IR Calculator'!C14+(15-0.5)*('IR Calculator'!C15-'IR Calculator'!C14)/MIN('IR Calculator'!C16,500))*0.000001)^5))/(EXP(MIN('IR Calculator'!$C$5*'IR Calculator'!$C$6/((('IR Calculator'!C14+(15-0.5)*('IR Calculator'!C15-'IR Calculator'!C14)/MIN('IR Calculator'!C16,500))*0.000001)*'IR Calculator'!$C$7*'IR Calculator'!$C$19),700))-1)*0.000001 -> 52.320664
B26: 16 | C26: ='IR Calculator'!C14+(16-0.5)*('IR Calculator'!C15-'IR Calculator'!C14)/MIN('IR Calculator'!C16,500) -> 8.062 | D26: =('IR Calculator'!C15-'IR Calculator'!C14)/MIN('IR Calculator'!C16,500) -> 0.004 | E26: =(2*'IR Calculator'!$C$5*'IR Calculator'!$C$6^2/((('IR Calculator'!C14+(16-0.5)*('IR Calculator'!C15-'IR Calculator'!C14)/MIN('IR Calculator'!C16,500))*0.000001)^5))/(EXP(MIN('IR Calculator'!$C$5*'IR Calculator'!$C$6/((('IR Calculator'!C14+(16-0.5)*('IR Calculator'!C15-'IR Calculator'!C14)/MIN('IR Calculator'!C16,500))*0.000001)*'IR Calculator'!$C$7*'IR Calculator'!$C$19),700))-1)*0.000001 -> 52.302013
B27: 17 | C27: ='IR Calculator'!C14+(17-0.5)*('IR Calculator'!C15-'IR Calculator'!C14)/MIN('IR Calculator'!C16,500) -> 8.066 | D27: =('IR Calculator'!C15-'IR Calculator'!C14)/MIN('IR Calculator'!C16,500) -> 0.004 | E27: =(2*'IR Calculator'!$C$5*'IR Calculator'!$C$6^2/((('IR Calculator'!C14+(17-0.5)*('IR Calculator'!C15-'IR Calculator'!C14)/MIN('IR Calculator'!C16,500))*0.000001)^5))/(EXP(MIN('IR Calculator'!$C$5*'IR Calculator'!$C$6/((('IR Calculator'!C14+(17-0.5)*('IR Calculator'!C15-'IR Calculator'!C14)/MIN('IR Calculator'!C16,500))*0.000001)*'IR Calculator'!$C$7*'IR Calculator'!$C$19),700))-1)*0.000001 -> 52.283326
B28: 18 | C28: ='IR Calculator'!C14+(18-0.5)*('IR Calculator'!C15-'IR Calculator'!C14)/MIN('IR Calculator'!C16,500) -> 8.07 | D28: =('IR Calculator'!C15-'IR Calculator'!C14)/MIN('IR Calculator'!C16,500) -> 0.004 | E28: =(2*'IR Calculator'!$C$5*'IR Calculator'!$C$6^2/((('IR Calculator'!C14+(18-0.5)*('IR Calculator'!C15-'IR Calculator'!C14)/MIN('IR Calculator'!C16,500))*0.000001)^5))/(EXP(MIN('IR Calculator'!$C$5*'IR Calculator'!$C$6/((('IR Calculator'!C14+(18-0.5)*('IR Calculator'!C15-'IR Calculator'!C14)/MIN('IR Calculator'!C16,500))*0.000001)*'IR Calculator'!$C$7*'IR Calculator'!$C$19),700))-1)*0.000001 -> 52.264604
B29: 19 | C29: ='IR Calculator'!C14+(19-0.5)*('IR Calculator'!C15-'IR Calculator'!C14)/MIN('IR Calculator'!C16,500) -> 8.074 | D29: =('IR Calculator'!C15-'IR Calculator'!C14)/MIN('IR Calculator'!C16,500) -> 0.004 | E29: =(2*'IR Calculator'!$C$5*'IR Calculator'!$C$6^2/((('IR Calculator'!C14+(19-0.5)*('IR Calculator'!C15-'IR Calculator'!C14)/MIN('IR Calculator'!C16,500))*0.000001)^5))/(EXP(MIN('IR Calculator'!$C$5*'IR Calculator'!$C$6/((('IR Calculator'!C14+(19-0.5)*('IR Calculator'!C15-'IR Calculator'!C14)/MIN('IR Calculator'!C16,500))*0.000001)*'IR Calculator'!$C$7*'IR Calculator'!$C$19),700))-1)*0.000001 -> 52.245847
B30: 20 | C30: ='IR Calculator'!C14+(20-0.5)*('IR Calculator'!C15-'IR Calculator'!C14)/MIN('IR Calculator'!C16,500) -> 8.078 | D30: =('IR Calculator'!C15-'IR Calculator'!C14)/MIN('IR Calculator'!C16,500) -> 0.004 | E30: =(2*'IR Calculator'!$C$5*'IR Calculator'!$C$6^2/((('IR Calculator'!C14+(20-0.5)*('IR Calculator'!C15-'IR Calculator'!C14)/MIN('IR Calculator'!C16,500))*0.000001)^5))/(EXP(MIN('IR Calculator'!$C$5*'IR Calculator'!$C$6/((('IR Calculator'!C14+(20-0.5)*('IR Calculator'!C15-'IR Calculator'!C14)/MIN('IR Calculator'!C16,500))*0.000001)*'IR Calculator'!$C$7*'IR Calculator'!$C$19),700))-1)*0.000001 -> 52.227054
B31: 21 | C31: ='IR Calculator'!C14+(21-0.5)*('IR Calculator'!C15-'IR Calculator'!C14)/MIN('IR Calculator'!C16,500) -> 8.082 | D31: =('IR Calculator'!C15-'IR Calculator'!C14)/MIN('IR Calculator'!C16,500) -> 0.004 | E31: =(2*'IR Calculator'!$C$5*'IR Calculator'!$C$6^2/((('IR Calculator'!C14+(21-0.5)*('IR Calculator'!C15-'IR Calculator'!C14)/MIN('IR Calculator'!C16,500))*0.000001)^5))/(EXP(MIN('IR Calculator'!$C$5*'IR Calculator'!$C$6/((('IR Calculator'!C14+(21-0.5)*('IR Calculator'!C15-'IR Calculator'!C14)/MIN('IR Calculator'!C16,500))*0.000001)*'IR Calculator'!$C$7*'IR Calculator'!$C$19),700))-1)*0.000001 -> 52.208226
B32: 22 | C32: ='IR Calculator'!C14+(22-0.5)*('IR Calculator'!C15-'IR Calculator'!C14)/MIN('IR Calculator'!C16,500) -> 8.086 | D32: =('IR Calculator'!C15-'IR Calculator'!C14)/MIN('IR Calculator'!C16,500) -> 0.004 | E32: =(2*'IR Calculator'!$C$5*'IR Calculator'!$C$6^2/((('IR Calculator'!C14+(22-0.5)*('IR Calculator'!C15-'IR Calculator'!C14)/MIN('IR Calculator'!C16,500))*0.000001)^5))/(EXP(MIN('IR Calculator'!$C$5*'IR Calculator'!$C$6/((('IR Calculator'!C14+(22-0.5)*('IR Calculator'!C15-'IR Calculator'!C14)/MIN('IR Calculator'!C16,500))*0.000001)*'IR Calculator'!$C$7*'IR Calculator'!$C$19),700))-1)*0.000001 -> 52.189363
B33: 23 | C33: ='IR Calculator'!C14+(23-0.5)*('IR Calculator'!C15-'IR Calculator'!C14)/MIN('IR Calculator'!C16,500) -> 8.09 | D33: =('IR Calculator'!C15-'IR Calculator'!C14)/MIN('IR Calculator'!C16,500) -> 0.004 | E33: =(2*'IR Calculator'!$C$5*'IR Calculator'!$C$6^2/((('IR Calculator'!C14+(23-0.5)*('IR Calculator'!C15-'IR Calculator'!C14)/MIN('IR Calculator'!C16,500))*0.000001)^5))/(EXP(MIN('IR Calculator'!$C$5*'IR Calculator'!$C$6/((('IR Calculator'!C14+(23-0.5)*('IR Calculator'!C15-'IR Calculator'!C14)/MIN('IR Calculator'!C16,500))*0.000001)*'IR Calculator'!$C$7*'IR Calculator'!$C$19),700))-1)*0.000001 -> 52.170465
B34: 24 | C34: ='IR Calculator'!C14+(24-0.5)*('IR Calculator'!C15-'IR Calculator'!C14)/MIN('IR Calculator'!C16,500) -> 8.094 | D34: =('IR Calculator'!C15-'IR Calculator'!C14)/MIN('IR Calculator'!C16,500) -> 0.004 | E34: =(2*'IR Calculator'!$C$5*'IR Calculator'!$C$6^2/((('IR Calculator'!C14+(24-0.5)*('IR Calculator'!C15-'IR Calculator'!C14)/MIN('IR Calculator'!C16,500))*0.000001)^5))/(EXP(MIN('IR Calculator'!$C$5*'IR Calculator'!$C$6/((('IR Calculator'!C14+(24-0.5)*('IR Calculator'!C15-'IR Calculator'!C14)/MIN('IR Calculator'!C16,500))*0.000001)*'IR Calculator'!$C$7*'IR Calculator'!$C$19),700))-1)*0.000001 -> 52.151532
B35: 25 | C35: ='IR Calculator'!C14+(25-0.5)*('IR Calculator'!C15-'IR Calculator'!C14)/MIN('IR Calculator'!C16,500) -> 8.098 | D35: =('IR Calculator'!C15-'IR Calculator'!C14)/MIN('IR Calculator'!C16,500) -> 0.004 | E35: =(2*'IR Calculator'!$C$5*'IR Calculator'!$C$6^2/((('IR Calculator'!C14+(25-0.5)*('IR Calculator'!C15-'IR Calculator'!C14)/MIN('IR Calculator'!C16,500))*0.000001)^5))/(EXP(MIN('IR Calculator'!$C$5*'IR Calculator'!$C$6/((('IR Calculator'!C14+(25-0.5)*('IR Calculator'!C15-'IR Calculator'!C14)/MIN('IR Calculator'!C16,500))*0.000001)*'IR Calculator'!$C$7*'IR Calculator'!$C$19),700))-1)*0.000001 -> 52.132565
B36: 26 | C36: ='IR Calculator'!C14+(26-0.5)*('IR Calculator'!C15-'IR Calculator'!C14)/MIN('IR Calculator'!C16,500) -> 8.102 | D36: =('IR Calculator'!C15-'IR Calculator'!C14)/MIN('IR Calculator'!C16,500) -> 0.004 | E36: =(2*'IR Calculator'!$C$5*'IR Calculator'!$C$6^2/((('IR Calculator'!C14+(26-0.5)*('IR Calculator'!C15-'IR Calculator'!C14)/MIN('IR Calculator'!C16,500))*0.000001)^5))/(EXP(MIN('IR Calculator'!$C$5*'IR Calculator'!$C$6/((('IR Calculator'!C14+(26-0.5)*('IR Calculator'!C15-'IR Calculator'!C14)/MIN('IR Calculator'!C16,500))*0.000001)*'IR Calculator'!$C$7*'IR Calculator'!$C$19),700))-1)*0.000001 -> 52.113564
B37: 27 | C37: ='IR Calculator'!C14+(27-0.5)*('IR Calculator'!C15-'IR Calculator'!C14)/MIN('IR Calculator'!C16,500) -> 8.106 | D37: =('IR Calculator'!C15-'IR Calculator'!C14)/MIN('IR Calculator'!C16,500) -> 0.004 | E37: =(2*'IR Calculator'!$C$5*'IR Calculator'!$C$6^2/((('IR Calculator'!C14+(27-0.5)*('IR Calculator'!C15-'IR Calculator'!C14)/MIN('IR Calculator'!C16,500))*0.000001)^5))/(EXP(MIN('IR Calculator'!$C$5*'IR Calculator'!$C$6/((('IR Calculator'!C14+(27-0.5)*('IR Calculator'!C15-'IR Calculator'!C14)/MIN('IR Calculator'!C16,500))*0.000001)*'IR Calculator'!$C$7*'IR Calculator'!$C$19),700))-1)*0.000001 -> 52.094528
B38: 28 | C38: ='IR Calculator'!C14+(28-0.5)*('IR Calculator'!C15-'IR Calculator'!C14)/MIN('IR Calculator'!C16,500) -> 8.11 | D38: =('IR Calculator'!C15-'IR Calculator'!C14)/MIN('IR Calculator'!C16,500) -> 0.004 | E38: =(2*'IR Calculator'!$C$5*'IR Calculator'!$C$6^2/((('IR Calculator'!C14+(28-0.5)*('IR Calculator'!C15-'IR Calculator'!C14)/MIN('IR Calculator'!C16,500))*0.000001)^5))/(EXP(MIN('IR Calculator'!$C$5*'IR Calculator'!$C$6/((('IR Calculator'!C14+(28-0.5)*('IR Calculator'!C15-'IR Calculator'!C14)/MIN('IR Calculator'!C16,500))*0.000001)*'IR Calculator'!$C$7*'IR Calculator'!$C$19),700))-1)*0.000001 -> 52.075458
B39: 29 | C39: ='IR Calculator'!C14+(29-0.5)*('IR Calculator'!C15-'IR Calculator'!C14)/MIN('IR Calculator'!C16,500) -> 8.114 | D39: =('IR Calculator'!C15-'IR Calculator'!C14)/MIN('IR Calculator'!C16,500) -> 0.004 | E39: =(2*'IR Calculator'!$C$5*'IR Calculator'!$C$6^2/((('IR Calculator'!C14+(29-0.5)*('IR Calculator'!C15-'IR Calculator'!C14)/MIN('IR Calculator'!C16,500))*0.000001)^5))/(EXP(MIN('IR Calculator'!$C$5*'IR Calculator'!$C$6/((('IR Calculator'!C14+(29-0.5)*('IR Calculator'!C15-'IR Calculator'!C14)/MIN('IR Calculator'!C16,500))*0.000001)*'IR Calculator'!$C$7*'IR Calculator'!$C$19),700))-1)*0.000001 -> 52.056353
B40: 30 | C40: ='IR Calculator'!C14+(30-0.5)*('IR Calculator'!C15-'IR Calculator'!C14)/MIN('IR Calculator'!C16,500) -> 8.118 | D40: =('IR Calculator'!C15-'IR Calculator'!C14)/MIN('IR Calculator'!C16,500) -> 0.004 | E40: =(2*'IR Calculator'!$C$5*'IR Calculator'!$C$6^2/((('IR Calculator'!C14+(30-0.5)*('IR Calculator'!C15-'IR Calculator'!C14)/MIN('IR Calculator'!C16,500))*0.000001)^5))/(EXP(MIN('IR Calculator'!$C$5*'IR Calculator'!$C$6/((('IR Calculator'!C14+(30-0.5)*('IR Calculator'!C15-'IR Calculator'!C14)/MIN('IR Calculator'!C16,500))*0.000001)*'IR Calculator'!$C$7*'IR Calculator'!$C$19),700))-1)*0.000001 -> 52.037215
B41: 31 | C41: ='IR Calculator'!C14+(31-0.5)*('IR Calculator'!C15-'IR Calculator'!C14)/MIN('IR Calculator'!C16,500) -> 8.122 | D41: =('IR Calculator'!C15-'IR Calculator'!C14)/MIN('IR Calculator'!C16,500) -> 0.004 | E41: =(2*'IR Calculator'!$C$5*'IR Calculator'!$C$6^2/((('IR Calculator'!C14+(31-0.5)*('IR Calculator'!C15-'IR Calculator'!C14)/MIN('IR Calculator'!C16,500))*0.000001)^5))/(EXP(MIN('IR Calculator'!$C$5*'IR Calculator'!$C$6/((('IR Calculator'!C14+(31-0.5)*('IR Calculator'!C15-'IR Calculator'!C14)/MIN('IR Calculator'!C16,500))*0.000001)*'IR Calculator'!$C$7*'IR Calculator'!$C$19),700))-1)*0.000001 -> 52.018043
B42: 32 | C42: ='IR Calculator'!C14+(32-0.5)*('IR Calculator'!C15-'IR Calculator'!C14)/MIN('IR Calculator'!C16,500) -> 8.126 | D42: =('IR Calculator'!C15-'IR Calculator'!C14)/MIN('IR Calculator'!C16,500) -> 0.004 | E42: =(2*'IR Calculator'!$C$5*'IR Calculator'!$C$6^2/((('IR Calculator'!C14+(32-0.5)*('IR Calculator'!C15-'IR Calculator'!C14)/MIN('IR Calculator'!C16,500))*0.000001)^5))/(EXP(MIN('IR Calculator'!$C$5*'IR Calculator'!$C$6/((('IR Calculator'!C14+(32-0.5)*('IR Calculator'!C15-'IR Calculator'!C14)/MIN('IR Calculator'!C16,500))*0.000001)*'IR Calculator'!$C$7*'IR Calculator'!$C$19),700))-1)*0.000001 -> 51.998838
B43: 33 | C43: ='IR Calculator'!C14+(33-0.5)*('IR Calculator'!C15-'IR Calculator'!C14)/MIN('IR Calculator'!C16,500) -> 8.13 | D43: =('IR Calculator'!C15-'IR Calculator'!C14)/MIN('IR Calculator'!C16,500) -> 0.004 | E43: =(2*'IR Calculator'!$C$5*'IR Calculator'!$C$6^2/((('IR Calculator'!C14+(33-0.5)*('IR Calculator'!C15-'IR Calculator'!C14)/MIN('IR Calculator'!C16,500))*0.000001)^5))/(EXP(MIN('IR Calculator'!$C$5*'IR Calculator'!$C$6/((('IR Calculator'!C14+(33-0.5)*('IR Calculator'!C15-'IR Calculator'!C14)/MIN('IR Calculator'!C16,500))*0.000001)*'IR Calculator'!$C$7*'IR Calculator'!$C$19),700))-1)*0.000001 -> 51.979599
B44: 34 | C44: ='IR Calculator'!C14+(34-0.5)*('IR Calculator'!C15-'IR Calculator'!C14)/MIN('IR Calculator'!C16,500) -> 8.134 | D44: =('IR Calculator'!C15-'IR Calculator'!C14)/MIN('IR Calculator'!C16,500) -> 0.004 | E44: =(2*'IR Calculator'!$C$5*'IR Calculator'!$C$6^2/((('IR Calculator'!C14+(34-0.5)*('IR Calculator'!C15-'IR Calculator'!C14)/MIN('IR Calculator'!C16,500))*0.000001)^5))/(EXP(MIN('IR Calculator'!$C$5*'IR Calculator'!$C$6/((('IR Calculator'!C14+(34-0.5)*('IR Calculator'!C15-'IR Calculator'!C14)/MIN('IR Calculator'!C16,500))*0.000001)*'IR Calculator'!$C$7*'IR Calculator'!$C$19),700))-1)*0.000001 -> 51.960326
...

Sheet Comparison
B1: Side-by-Side Object Comparison (edit yellow cells)
B3: Parameter | C3: Object A | D3: Object B | E3: Object C | F3: Object D
B4: Temperature (°C) | C4: 150 | D4: 200 | E4: 100 | F4: 250
B5: Surface Area (m²) | C5: 0.117 | D5: 0.047 | E5: 0.2 | F5: 0.03
B6: Emissivity ε | C6: 0.96 | D6: 0.96 | E6: 0.9 | F6: 0.15
B7: λ₁ — Band start (µm) | C7: 8 | D7: 8 | E7: 8 | F7: 8
B8: λ₂ — Band end (µm) | C8: 10 | D8: 10 | E8: 10 | F8: 10
B10: Result | C10: Object A | D10: Object B | E10: Object C | F10: Object D
B11: T (K) | C11: =C4+273.15 -> 423.15 | D11: =D4+273.15 -> 473.15 | E11: =E4+273.15 -> 373.15 | F11: =F4+273.15 -> 523.15
B12: Peak λ (µm) | C12: =2897.8/(C4+273.15) -> 6.8481626 | D12: =2897.8/(D4+273.15) -> 6.1244848 | E12: =2897.8/(E4+273.15) -> 7.7657778 | F12: =2897.8/(F4+273.15) -> 5.5391379
B13: P_total (W) | C13: =C6*'IR Calculator'!$C$8*(C4+273.15)^4*C5 -> 204.19552 | D13: =D6*'IR Calculator'!$C$8*(D4+273.15)^4*D5 -> 128.22603 | E13: =E6*'IR Calculator'!$C$8*(E4+273.15)^4*E5 -> 197.88735 | F13: =F6*'IR Calculator'!$C$8*(F4+273.15)^4*F5 -> 19.113014
B14: P_band (W) | C14: =C6*C5*PI()*SUMPRODUCT(((C8-C7)/200)*((2*'IR Calculator'!$C$5*'IR Calculator'!$C$6^2/(((C7+(ROW(INDIRECT("1:200"))-0.5)*((C8-C7)/200))*0.000001)^5)/(EXP(MIN('IR Calculator'!$C$5*'IR Calculator'!$C$6/(((C7+(ROW(INDIRECT("1:200"))-0.5)*((C8-C7)/200))*0.000001)*'IR Calculator'!$C$7*(C4+273.15)),700))-1)*0.000001)))*0.000001 -> 5.2187305e-05 | D14: =D6*D5*PI()*SUMPRODUCT(((D8-D7)/200)*((2*'IR Calculator'!$C$5*'IR Calculator'!$C$6^2/(((D7+(ROW(INDIRECT("1:200"))-0.5)*((D8-D7)/200))*0.000001)^5)/(EXP(MIN('IR Calculator'!$C$5*'IR Calculator'!$C$6/(((D7+(ROW(INDIRECT("1:200"))-0.5)*((D8-D7)/200))*0.000001)*'IR Calculator'!$C$7*(D4+273.15)),700))-1)*0.000001)))*0.000001 -> 3.0487682e-05 | E14: =E6*E5*PI()*SUMPRODUCT(((E8-E7)/200)*((2*'IR Calculator'!$C$5*'IR Calculator'!$C$6^2/(((E7+(ROW(INDIRECT("1:200"))-0.5)*((E8-E7)/200))*0.000001)^5)/(EXP(MIN('IR Calculator'!$C$5*'IR Calculator'!$C$6/(((E7+(ROW(INDIRECT("1:200"))-0.5)*((E8-E7)/200))*0.000001)*'IR Calculator'!$C$7*(E4+273.15)),700))-1)*0.000001)))*0.000001 -> 5.2356619e-05 | F14: =F6*F5*PI()*SUMPRODUCT(((F8-F7)/200)*((2*'IR Calculator'!$C$5*'IR Calculator'!$C$6^2/(((F7+(ROW(INDIRECT("1:200"))-0.5)*((F8-F7)/200))*0.000001)^5)/(EXP(MIN('IR Calculator'!$C$5*'IR Calculator'!$C$6/(((F7+(ROW(INDIRECT("1:200"))-0.5)*((F8-F7)/200))*0.000001)*'IR Calculator'!$C$7*(F4+273.15)),700))-1)*0.000001)))*0.000001 -> 4.1367252e-06
B15: Band fraction | C15: =C14/C13 -> 2.5557517e-07 | D15: =D14/D13 -> 2.3776515e-07 | E15: =E14/E13 -> 2.645779e-07 | F15: =F14/F13 -> 2.1643501e-07
B16: Band irradiance W/m² | C16: =C14/C5 -> 0.00044604534 | D16: =D14/D5 -> 0.00064867407 | E16: =E14/E5 -> 0.0002617831 | F16: =F14/F5 -> 0.00013789084
B19: Quick Emissivity Reference
B20: Water / ice | E20: 0.95–0.97
B21: Human skin | E21: 0.97–0.99
B22: Painted surfaces | E22: 0.90–0.95
B23: Concrete / asphalt | E23: 0.90–0.97
B24: Wood | E24: 0.90–0.95
B25: Oxidised steel | E25: 0.70–0.80
B26: Polished copper | E26: 0.03–0.05
B27: Polished aluminium | E27: 0.04–0.06
